<mujoco model="GZ_DW_sub01">
  <compiler angle="radian" boundmass="0.001" boundinertia="0.001"/>
  <option timestep="0.00416667" iterations="1" ls_iterations="4">
    <flag eulerdamp="disable" warmstart="disable"/>
  </option>
  <size njmax="1000" nconmax="400" nuser_jnt="1"/>
  <visual>
    <global offwidth="800"/>
  </visual>
  <visual>
    <global offheight="800"/>
  </visual>
  <default class="main">
    <joint stiffness="1" limited="true" armature="0.01" damping="1"/>
    <geom contype="0" conaffinity="0" margin="0.001" rgba="0.8 0.6 0.4 1"/>
    <site size="0.001 0.005 0.005"/>
    <tendon limited="false" width="0.001" rgba="0.95 0.3 0.3 1"/>
    <general ctrllimited="true" ctrlrange="-1 1"/>
    <default class="coll">
      <geom type="capsule" contype="1" group="1" rgba="0.8 0.7 0.5 1" margin="0.001"/>
    </default>
  </default>
  <asset>
    <texture type="skybox" builtin="flat" rgb1="1 1 1" rgb2="1 1 1" width="100" height="600"/>
    <texture type="cube" name="texgeom" builtin="flat" mark="cross" rgb1="1 1 1" rgb2="1 1 1" markrgb="1 1 1" width="127" height="762"/>
    <texture type="2d" name="texplane" builtin="checker" rgb1="1 1 1" rgb2="1 1 1" width="100" height="100"/>
    <material name="MatPlane" texture="texplane" texuniform="true" reflectance="0.0"/>
    <material name="geom" texture="texgeom" texuniform="true"/>
    <mesh name="sacrum" file="meshes/sacrum.stl" scale="1.02105 1.02105 1.02105"/>
    <mesh name="pelvis" file="meshes/pelvis.stl" scale="1.02105 1.02105 1.02105"/>
    <mesh name="l_pelvis" file="meshes/l_pelvis.stl" scale="1.02105 1.02105 1.02105"/>
    <mesh name="femur_r" file="meshes/femur_r.stl" scale="0.908907 0.908907 0.908907"/>
    <mesh name="tibia_r" file="meshes/tibia_r.stl" scale="1.11668 1.11668 1.11668"/>
    <mesh name="fibula_r" file="meshes/fibula_r.stl" scale="1.11668 1.11668 1.11668"/>
    <mesh name="talus_rv" file="meshes/talus_rv.stl" scale="1.11668 1.11668 1.11668"/>
    <mesh name="foot" file="meshes/foot.stl" scale="1.06552 1.06552 1.06552"/>
    <mesh name="bofoot" file="meshes/bofoot.stl" scale="1.06552 1.06552 1.06552"/>
    <mesh name="femur_l" file="meshes/femur_l.stl" scale="0.908907 0.908907 0.908907"/>
    <mesh name="tibia_l" file="meshes/tibia_l.stl" scale="1.11668 1.11668 1.11668"/>
    <mesh name="fibula_l" file="meshes/fibula_l.stl" scale="1.11668 1.11668 1.11668"/>
    <mesh name="talus_lv" file="meshes/talus_lv.stl" scale="1.11668 1.11668 1.11668"/>
    <mesh name="l_foot" file="meshes/l_foot.stl" scale="1.06552 1.06552 1.06552"/>
    <mesh name="l_bofoot" file="meshes/l_bofoot.stl" scale="1.06552 1.06552 1.06552"/>
    <mesh name="hat_spine" file="meshes/hat_spine.stl" scale="1.07736 1.07736 1.07736"/>
    <mesh name="hat_jaw" file="meshes/hat_jaw.stl" scale="1.07736 1.07736 1.07736"/>
    <mesh name="hat_skull" file="meshes/hat_skull.stl" scale="1.07736 1.07736 1.07736"/>
    <mesh name="hat_ribs_scap" file="meshes/hat_ribs_scap.stl" scale="1.07736 1.07736 1.07736"/>
    <mesh name="humerus_rv" file="meshes/humerus_rv.stl" scale="1.17477 1.17477 1.17477"/>
    <mesh name="ulna_rv" file="meshes/ulna_rv.stl" scale="1.10827 1.10827 1.10827"/>
    <mesh name="radius_rv" file="meshes/radius_rv.stl" scale="1.10827 1.10827 1.10827"/>
    <mesh name="pisiform_rvs" file="meshes/pisiform_rvs.stl" scale="0.905691 0.905691 0.905691"/>
    <mesh name="lunate_rvs" file="meshes/lunate_rvs.stl" scale="0.905691 0.905691 0.905691"/>
    <mesh name="scaphoid_rvs" file="meshes/scaphoid_rvs.stl" scale="0.905691 0.905691 0.905691"/>
    <mesh name="triquetrum_rvs" file="meshes/triquetrum_rvs.stl" scale="0.905691 0.905691 0.905691"/>
    <mesh name="hamate_rvs" file="meshes/hamate_rvs.stl" scale="0.905691 0.905691 0.905691"/>
    <mesh name="capitate_rvs" file="meshes/capitate_rvs.stl" scale="0.905691 0.905691 0.905691"/>
    <mesh name="trapezoid_rvs" file="meshes/trapezoid_rvs.stl" scale="0.905691 0.905691 0.905691"/>
    <mesh name="trapezium_rvs" file="meshes/trapezium_rvs.stl" scale="0.905691 0.905691 0.905691"/>
    <mesh name="metacarpal2_rvs" file="meshes/metacarpal2_rvs.stl" scale="0.905691 0.905691 0.905691"/>
    <mesh name="index_proximal_rvs" file="meshes/index_proximal_rvs.stl" scale="0.905691 0.905691 0.905691"/>
    <mesh name="index_medial_rvs" file="meshes/index_medial_rvs.stl" scale="0.905691 0.905691 0.905691"/>
    <mesh name="index_distal_rvs" file="meshes/index_distal_rvs.stl" scale="0.905691 0.905691 0.905691"/>
    <mesh name="metacarpal3_rvs" file="meshes/metacarpal3_rvs.stl" scale="0.905691 0.905691 0.905691"/>
    <mesh name="middle_proximal_rvs" file="meshes/middle_proximal_rvs.stl" scale="0.905691 0.905691 0.905691"/>
    <mesh name="middle_medial_rvs" file="meshes/middle_medial_rvs.stl" scale="0.905691 0.905691 0.905691"/>
    <mesh name="middle_distal_rvs" file="meshes/middle_distal_rvs.stl" scale="0.905691 0.905691 0.905691"/>
    <mesh name="metacarpal4_rvs" file="meshes/metacarpal4_rvs.stl" scale="0.905691 0.905691 0.905691"/>
    <mesh name="ring_proximal_rvs" file="meshes/ring_proximal_rvs.stl" scale="0.905691 0.905691 0.905691"/>
    <mesh name="ring_medial_rvs" file="meshes/ring_medial_rvs.stl" scale="0.905691 0.905691 0.905691"/>
    <mesh name="ring_distal_rvs" file="meshes/ring_distal_rvs.stl" scale="0.905691 0.905691 0.905691"/>
    <mesh name="metacarpal5_rvs" file="meshes/metacarpal5_rvs.stl" scale="0.905691 0.905691 0.905691"/>
    <mesh name="little_proximal_rvs" file="meshes/little_proximal_rvs.stl" scale="0.905691 0.905691 0.905691"/>
    <mesh name="little_medial_rvs" file="meshes/little_medial_rvs.stl" scale="0.905691 0.905691 0.905691"/>
    <mesh name="little_distal_rvs" file="meshes/little_distal_rvs.stl" scale="0.905691 0.905691 0.905691"/>
    <mesh name="metacarpal1_rvs" file="meshes/metacarpal1_rvs.stl" scale="0.905691 0.905691 0.905691"/>
    <mesh name="thumb_proximal_rvs" file="meshes/thumb_proximal_rvs.stl" scale="0.905691 0.905691 0.905691"/>
    <mesh name="thumb_distal_rvs" file="meshes/thumb_distal_rvs.stl" scale="0.905691 0.905691 0.905691"/>
    <mesh name="humerus_lv" file="meshes/humerus_lv.stl" scale="1.17477 1.17477 1.17477"/>
    <mesh name="ulna_lv" file="meshes/ulna_lv.stl" scale="1.10827 1.10827 1.10827"/>
    <mesh name="radius_lv" file="meshes/radius_lv.stl" scale="1.10827 1.10827 1.10827"/>
    <mesh name="pisiform_lvs" file="meshes/pisiform_lvs.stl" scale="0.905691 0.905691 0.905691"/>
    <mesh name="lunate_lvs" file="meshes/lunate_lvs.stl" scale="0.905691 0.905691 0.905691"/>
    <mesh name="scaphoid_lvs" file="meshes/scaphoid_lvs.stl" scale="0.905691 0.905691 0.905691"/>
    <mesh name="triquetrum_lvs" file="meshes/triquetrum_lvs.stl" scale="0.905691 0.905691 0.905691"/>
    <mesh name="hamate_lvs" file="meshes/hamate_lvs.stl" scale="0.905691 0.905691 0.905691"/>
    <mesh name="capitate_lvs" file="meshes/capitate_lvs.stl" scale="0.905691 0.905691 0.905691"/>
    <mesh name="trapezoid_lvs" file="meshes/trapezoid_lvs.stl" scale="0.905691 0.905691 0.905691"/>
    <mesh name="trapezium_lvs" file="meshes/trapezium_lvs.stl" scale="0.905691 0.905691 0.905691"/>
    <mesh name="metacarpal2_lvs" file="meshes/metacarpal2_lvs.stl" scale="0.905691 0.905691 0.905691"/>
    <mesh name="index_proximal_lvs" file="meshes/index_proximal_lvs.stl" scale="0.905691 0.905691 0.905691"/>
    <mesh name="index_medial_lvs" file="meshes/index_medial_lvs.stl" scale="0.905691 0.905691 0.905691"/>
    <mesh name="index_distal_lvs" file="meshes/index_distal_lvs.stl" scale="0.905691 0.905691 0.905691"/>
    <mesh name="metacarpal3_lvs" file="meshes/metacarpal3_lvs.stl" scale="0.905691 0.905691 0.905691"/>
    <mesh name="middle_proximal_lvs" file="meshes/middle_proximal_lvs.stl" scale="0.905691 0.905691 0.905691"/>
    <mesh name="middle_medial_lvs" file="meshes/middle_medial_lvs.stl" scale="0.905691 0.905691 0.905691"/>
    <mesh name="middle_distal_lvs" file="meshes/middle_distal_lvs.stl" scale="0.905691 0.905691 0.905691"/>
    <mesh name="metacarpal4_lvs" file="meshes/metacarpal4_lvs.stl" scale="0.905691 0.905691 0.905691"/>
    <mesh name="ring_proximal_lvs" file="meshes/ring_proximal_lvs.stl" scale="0.905691 0.905691 0.905691"/>
    <mesh name="ring_medial_lvs" file="meshes/ring_medial_lvs.stl" scale="0.905691 0.905691 0.905691"/>
    <mesh name="ring_distal_lvs" file="meshes/ring_distal_lvs.stl" scale="0.905691 0.905691 0.905691"/>
    <mesh name="metacarpal5_lvs" file="meshes/metacarpal5_lvs.stl" scale="0.905691 0.905691 0.905691"/>
    <mesh name="little_proximal_lvs" file="meshes/little_proximal_lvs.stl" scale="0.905691 0.905691 0.905691"/>
    <mesh name="little_medial_lvs" file="meshes/little_medial_lvs.stl" scale="0.905691 0.905691 0.905691"/>
    <mesh name="little_distal_lvs" file="meshes/little_distal_lvs.stl" scale="0.905691 0.905691 0.905691"/>
    <mesh name="metacarpal1_lvs" file="meshes/metacarpal1_lvs.stl" scale="0.905691 0.905691 0.905691"/>
    <mesh name="thumb_proximal_lvs" file="meshes/thumb_proximal_lvs.stl" scale="0.905691 0.905691 0.905691"/>
    <mesh name="thumb_distal_lvs" file="meshes/thumb_distal_lvs.stl" scale="0.905691 0.905691 0.905691"/>
  </asset>
  <worldbody>
    <geom name="floor" size="500 500 0.125" type="plane" contype="1" conaffinity="1" group="2" material="MatPlane" rgba="1 1 1 1"/>
    <light pos="0 0 1.3" dir="0 0 -1" directional="true" castshadow="false" cutoff="100" exponent="1" diffuse="1 1 1" specular="0.1 0.1 0.1"/>
    <body name="pelvis" pos="0 0 0.975" quat="0.707107 0.707107 0 0">
      <inertial pos="-0.0721882 0 0" mass="13.573" diaginertia="0.123517 0.104653 0.0695686"/>
      <joint name="pelvis_tx" pos="0 0 0" axis="1 0 0" type="slide" stiffness="0" limited="false" range="-500 500" armature="0" damping="0"/>
      <joint name="pelvis_tz" pos="0 0 0" axis="0 0 1" type="slide" stiffness="0" limited="false" range="-300 300" armature="0" damping="0"/>
      <joint name="pelvis_ty" pos="0 0 0" axis="0 1 0" type="slide" stiffness="0" limited="false" range="-100 200" armature="0" damping="0"/>
      <joint name="pelvis_tilt" pos="0 0 0" axis="0 0 1" stiffness="0" limited="false" range="-1.5708 1.5708" armature="0" damping="0"/>
      <joint name="pelvis_list" pos="0 0 0" axis="1 0 0" stiffness="0" limited="false" range="-1.5708 1.5708" armature="0" damping="0"/>
      <joint name="pelvis_rotation" pos="0 0 0" axis="0 1 0" stiffness="0" limited="false" range="-1.5708 1.5708" armature="0" damping="0"/>
      <geom name="sacrum" type="mesh" mesh="sacrum"/>
      <geom name="pelvis" type="mesh" mesh="pelvis"/>
      <geom name="l_pelvis" type="mesh" mesh="l_pelvis"/>
      <!-- <site name="rasis" pos="-0.0219389 -0.00227135 0.143841" size="0.01"/>
      <site name="lasis" pos="-0.0219389 -0.00227135 -0.143841" size="0.01"/>
      <site name="rpsis" pos="-0.190785 0.0705299 0.0625177" size="0.01"/>
      <site name="lpsis" pos="-0.190785 0.0705299 -0.0625177" size="0.01"/>
      <site name="CHip" pos="-0.105673 0.0334961 0.000910482" size="0.01"/>
      <site name="RHip" pos="-0.169805 -0.0346575 0.10081" size="0.01"/>
      <site name="LHip" pos="-0.169805 -0.0346575 -0.10081" size="0.01"/>
      <site name="mhip" pos="-0.172699 -0.0336121 0.00126933" size="0.01"/>
      <site name="rbum" pos="-0.22695 -0.0711889 0.0781376" size="0.01"/>
      <site name="lbum" pos="-0.22695 -0.0711889 -0.0781376" size="0.01"/> -->
      <camera name="track" pos="0 0 4" mode="trackcom"/>
      <!-- <light name="spotlight" pos="0 10 2" dir="0 -1 0" mode="trackcom"/> -->
      <body name="femur_r" pos="-0.0721882 -0.0674914 0.0852576">
        <inertial pos="0 -0.154514 0" quat="0.5 0.5 -0.5 0.5" mass="10.7199" diaginertia="0.134436 0.127486 0.0334185"/>
        <joint name="hip_flexion_r" pos="0 0 0" axis="0 0 1" stiffness="10" range="-0.787 2.0944" damping="5"/>
        <joint name="hip_adduction_r" pos="0 0 0" axis="1 0 0" stiffness="10" range="-0.524 0.524" damping="5"/>
        <joint name="hip_rotation_r" pos="0 0 0" axis="0 1 0" stiffness="20" range="-2.0944 2.0944" damping="5"/>
        <geom name="femur_r" type="mesh" mesh="femur_r"/>
        <!-- <site name="rthigh" pos="-0.00674545 -0.0342306 0.106869" size="0.01"/>
        <site name="rfrontthigh" pos="0.076145 -0.166172 0.0094889" size="0.01"/>
        <site name="rfrontinnerthigh" pos="0.0678635 -0.267824 -0.0331186" size="0.01"/> -->
        <body name="tibia_r" pos="-0.00167398 -0.365545 0">
          <inertial pos="0 -0.208485 0" quat="0.5 0.5 -0.5 0.5" mass="4.27289" diaginertia="0.073438 0.072432 0.00732943"/>
          <joint name="knee_angle_r" pos="0 0 0" axis="0 0 1" range="-2.7925 0.174533"/>
          <geom name="tibia_r" type="mesh" mesh="tibia_r"/>
          <geom name="fibula_r" type="mesh" mesh="fibula_r"/>
          <!-- <site name="RKnee" pos="0.00728611 -0.0175738 -0.00496484" size="0.01"/>
          <site name="rknem" pos="0.013188 -0.0170056 0.0531986" size="0.01"/>
          <site name="rinnerknee" pos="0.00344908 -0.0227503 -0.0633382" size="0.01"/>
          <site name="rshin" pos="0.00642417 -0.151537 0.062612" size="0.01"/> -->
          <body name="talus_r" pos="0 -0.480173 0">
            <inertial pos="0 0 0" mass="0.11525" diaginertia="0.00143714 0.00143714 0.00143714"/>
            <joint name="ankle_angle_r" pos="0 0 0" axis="-0.105014 -0.174022 0.979126" stiffness="10" range="-1.5708 1.5708"/>
            <geom name="talus_rv" type="mesh" mesh="talus_rv"/>
            <!-- <site name="rankm" pos="-0.00609146 0.0174918 0.0446369" size="0.01"/>
            <site name="RAnkle" pos="-0.00819541 0.0267856 0.00464904" size="0.01"/> -->
            <body name="calcn_r" pos="-0.0544606 -0.0468448 0.00884412">
              <inertial pos="0.106552 0.0319656 0" quat="0 0.707107 0 0.707107" mass="1.44062" diaginertia="0.00536472 0.00510303 0.00183186"/>
              <joint name="subtalar_angle_r" pos="0 0 0" axis="0.78718 0.604747 -0.120949" range="-1.5708 1.5708"/>
              <geom name="r_foot" type="mesh" mesh="foot"/>
              <!-- <geom name="r_foot_col1" class="coll" size="0.02 0.0831039" pos="0.0925 0 -0.02" quat="0.6632 0 0.748442 0"/>
              <geom name="r_foot_col3" class="coll" size="0.02 0.0657647" pos="0.075 0 0.02" quat="0.758965 0 0.651131 0"/> -->
              <!-- <site name="RHeel" pos="-0.0161672 -0.00123484 -0.00612689" size="0.01"/>
              <site name="rfifthmetatarsal" pos="0.163141 -0.00757232 0.034868" size="0.01"/>
              <site name="rfirstmetatarsal" pos="0.180635 0.0222052 -0.0342573" size="0.01"/>
              <site name="RFoot" pos="0.220955 0.00145429 -0.00538186" size="0.01" rgba="0.5 0.5 1 1"/> -->
              <body name="toes_r" pos="0.190515 -0.00213104 0.00115076">
                <inertial pos="0.036867 0.00639311 -0.0186466" quat="0 0.707107 0 0.707107" mass="0.249631" diaginertia="0.00130847 0.001 0.001"/>
                <joint name="mtp_angle_r" pos="0 0 0" axis="-0.580954 0 0.813936" range="-1.5708 1.5708"/>
                <geom name="r_bofoot" type="mesh" mesh="bofoot"/>
                <!-- <geom name="r_bofoot_col1" class="coll" size="0.0175 0.045" pos="0.04 0 0.01" quat="0.400864 0 0.916138 0"/>
                <geom name="r_bofoot_col2" class="coll" size="0.02 0.04" pos="0.01 0 0" quat="0.305011 0 0.952349 0"/> -->
                <!-- <site name="RBigToe" pos="0.0557709 0.00815447 -0.0283971" size="0.01" rgba="0.5 0.5 1 1"/>
                <site name="rfourthtoe" pos="0.0334301 -0.00868028 0.0257094" size="0.01" rgba="0.5 0.5 1 1"/> -->
              </body>
            </body>
          </body>
        </body>
      </body>
      <body name="femur_l" pos="-0.0721882 -0.0674914 -0.0852576">
        <inertial pos="0 -0.154514 0" quat="0.5 0.5 -0.5 0.5" mass="10.7199" diaginertia="0.134436 0.127486 0.0334185"/>
        <joint name="hip_flexion_l" pos="0 0 0" axis="0 0 1" stiffness="10" range="-0.787 2.0944" damping="5"/>
        <joint name="hip_adduction_l" pos="0 0 0" axis="-1 0 0" stiffness="10" range="-0.524 0.524" damping="5"/>
        <joint name="hip_rotation_l" pos="0 0 0" axis="0 -1 0" stiffness="20" range="-2.0944 2.0944" damping="5"/>
        <geom name="femur_l" type="mesh" mesh="femur_l"/>
        <!-- <site name="lthigh" pos="-0.00674545 -0.0342306 -0.106869" size="0.01"/>
        <site name="lfrontthigh" pos="0.076145 -0.166172 -0.0094889" size="0.01"/>
        <site name="lfrontinnerthigh" pos="0.0678635 -0.267824 0.0331186" size="0.01"/> -->
        <body name="tibia_l" pos="-0.00167398 -0.365545 0">
          <inertial pos="0 -0.208485 0" quat="0.5 0.5 -0.5 0.5" mass="4.27289" diaginertia="0.073438 0.072432 0.00732943"/>
          <joint name="knee_angle_l" pos="0 0 0" axis="0 0 1" range="-2.7925 0.174533"/>
          <geom name="tibia_l" type="mesh" mesh="tibia_l"/>
          <geom name="fibula_l" type="mesh" mesh="fibula_l"/>
          <!-- <site name="LKnee" pos="0.00728611 -0.0175738 0.00496484" size="0.01"/>
          <site name="lknem" pos="0.013188 -0.0170056 -0.0531986" size="0.01"/>
          <site name="linnerknee" pos="0.00344908 -0.0227503 0.0633382" size="0.01"/>
          <site name="lshin" pos="0.00642417 -0.151537 -0.062612" size="0.01"/> -->
          <body name="talus_l" pos="0 -0.480173 0">
            <inertial pos="0 0 0" mass="0.11525" diaginertia="0.00143714 0.00143714 0.00143714"/>
            <joint name="ankle_angle_l" pos="0 0 0" axis="0.105014 0.174022 0.979126" stiffness="10" range="-1.0472 1.0472"/>
            <geom name="talus_lv" type="mesh" mesh="talus_lv"/>
            <!-- <site name="lankm" pos="-0.00609146 0.0174918 -0.0446369" size="0.01"/>
            <site name="LAnkle" pos="-0.00819541 0.0267856 -0.00464904" size="0.01"/> -->
            <body name="calcn_l" pos="-0.0544606 -0.0468448 -0.00884412">
              <inertial pos="0.106552 0.0319656 0" quat="0 0.707107 0 0.707107" mass="1.44062" diaginertia="0.00536472 0.00510303 0.00183186"/>
              <joint name="subtalar_angle_l" pos="0 0 0" axis="-0.78718 -0.604747 -0.120949" range="-1.5708 1.5708"/>
              <geom name="l_foot" type="mesh" mesh="l_foot"/>
              <!-- <geom name="l_foot_col1" class="coll" size="0.02 0.0831039" pos="0.0925 0 0.02" quat="0.748442 0 0.6632 0"/>
              <geom name="l_foot_col3" class="coll" size="0.02 0.0657647" pos="0.075 0 -0.02" quat="0.651131 0 0.758965 0"/> -->
              <!-- <site name="LHeel" pos="-0.0161672 -0.00123484 0.00612689" size="0.01"/>
              <site name="lfifthmetatarsal" pos="0.163141 -0.00757232 -0.034868" size="0.01"/>
              <site name="lfirstmetatarsal" pos="0.180635 0.0222052 0.0342573" size="0.01"/>
              <site name="LFoot" pos="0.220955 0.00145429 0.00538186" size="0.01" rgba="0.5 0.5 1 1"/> -->
              <body name="toes_l" pos="0.190515 -0.00213104 -0.00115076">
                <inertial pos="0.036867 0.00639311 0.0186466" quat="0 0.707107 0 0.707107" mass="0.249631" diaginertia="0.00130847 0.001 0.001"/>
                <joint name="mtp_angle_l" pos="0 0 0" axis="0.580954 0 0.813936" range="-1.0472 1.0472"/>
                <geom name="l_bofoot" type="mesh" mesh="l_bofoot"/>
                <!-- <geom name="l_bofoot_col1" class="coll" size="0.0175 0.045" pos="0.04 0 -0.01" quat="0.400864 0 -0.916138 0"/>
                <geom name="l_bofoot_col2" class="coll" size="0.02 0.04" pos="0.01 0 0" quat="0.305011 0 -0.952349 0"/> -->
                <!-- <site name="LBigToe" pos="0.0557709 0.00815447 0.0283971" size="0.01" rgba="0.5 0.5 1 1"/>
                <site name="lfourthtoe" pos="0.0334301 -0.00868028 -0.0257094" size="0.01" rgba="0.5 0.5 1 1"/> -->
              </body>
            </body>
          </body>
        </body>
      </body>
      <body name="torso" pos="-0.10282 0.0832155 0">
        <inertial pos="-0.0323208 0.344755 0" quat="0.707107 0.707107 0 0" mass="30.9177" diaginertia="1.97246 1.9148 1.01064"/>
        <joint name="lumbar_extension" pos="0 0 0" axis="0 0 1" stiffness="10" range="-1.5708 0.377" damping="5"/>
        <joint name="lumbar_bending" pos="0 0 0" axis="1 0 0" stiffness="10" range="-0.754 0.754" damping="5"/>
        <joint name="lumbar_rotation" pos="0 0 0" axis="0 1 0" stiffness="20" range="-0.754 0.754" damping="5"/>
        <geom name="hat_spine" type="mesh" mesh="hat_spine"/>
        <geom name="hat_ribs_scap" type="mesh" mesh="hat_ribs_scap"/>
        <!-- <site name="sternum" pos="0.129954 0.23292 -0.00500331" size="0.01"/>
        <site name="umbilicus" pos="0.148857 0.0212547 0.00415021" size="0.01"/>
        <site name="upperback" pos="-0.0985789 0.167578 -0.00757428" size="0.01"/>
        <site name="rback" pos="-0.101555 0.414713 0.0933494" size="0.01"/>
        <site name="lback" pos="-0.101555 0.414713 -0.0933494" size="0.01"/>
        <site name="lscapula" pos="-0.116794 0.284777 -0.0958928" size="0.01"/>
        <site name="rscapula" pos="-0.116794 0.284777 0.0958928" size="0.01"/>
        <site name="rwaist" pos="0.0134005 0.11646 0.16282" size="0.01"/>
        <site name="lwaist" pos="0.0134005 0.11646 -0.16282" size="0.01"/>
        <site name="rbreast" pos="0.119027 0.241351 0.106505" size="0.01"/>
        <site name="lbreast" pos="0.119027 0.241351 -0.106505" size="0.01"/>
        <site name="rshom" pos="-0.0121523 0.408883 0.218321" size="0.01"/>
        <site name="lshom" pos="-0.0121523 0.408883 -0.218321" size="0.01"/>
        <site name="backneck" pos="-0.0722377 0.47708 -0.0185174" size="0.01"/>
        <site name="Neck" pos="0.00544366 0.44067 -0.0154065" size="0.01"/>
        <site name="clavicle" pos="0.0804364 0.404454 -0.0117544" size="0.01"/> -->
        <body name="head" pos="0 0.541458 0">
          <joint name="neck_extension" pos="0 0 0" axis="0 0 1" stiffness="10" range="-1.5708 0.377" damping="5"/>
          <joint name="neck_bending" pos="0 0 0" axis="1 0 0" stiffness="10" range="-0.754 0.754" damping="5"/>
          <joint name="neck_rotation" pos="0 0 0" axis="0 1 0" stiffness="20" range="-0.754 0.754" damping="5"/>
          <geom name="hat_jaw" pos="0 -0.541458 0" type="mesh" mesh="hat_jaw"/>
          <geom name="hat_skull" pos="0 -0.541458 0" type="mesh" mesh="hat_skull"/>
          <!-- <site name="Head" pos="0.025319 0.0865568 -0.0153891" size="0.01"/>
          <site name="rfronthead" pos="0.108104 0.13837 0.0568891" size="0.01"/>
          <site name="lfronthead" pos="0.108104 0.13837 -0.0568891" size="0.01"/>
          <site name="rbackhead" pos="-0.0560765 0.0443392 0.0608796" size="0.01"/>
          <site name="lbackhead" pos="-0.0560765 0.0443392 -0.0608796" size="0.01"/>
          <site name="rcheek" pos="0.118333 0.0332712 0.0611876" size="0.01"/>
          <site name="lcheek" pos="0.118333 0.0332712 -0.0611876" size="0.01"/> -->
        </body>
        <body name="humerus_r" pos="0.00339907 0.400239 0.183151">
          <inertial pos="0 -0.193252 0" quat="0.5 0.5 -0.5 0.5" mass="2.34246" diaginertia="0.0213276 0.0190007 0.00655464"/>
          <joint name="arm_flex_r" pos="0 0 0" axis="0 0 1" range="-1.5708 3.1416"/>
          <joint name="arm_add_r" pos="0 0 0" axis="1 0 0" range="-3.1415 1.5708"/>
          <joint name="arm_rot_r" pos="0 0 0" axis="0 1 0" range="-1.5708 1.5708"/>
          <geom name="humerus_rv" type="mesh" mesh="humerus_rv"/>
          <!-- <site name="RShoulder" pos="-0.00986901 -0.0475865 0.0400896" size="0.01"/>
          <site name="rupperarm" pos="-0.0143887 -0.13254 0.0641756" size="0.01"/> -->
          <body name="ulna_r" pos="0.0154412 -0.336305 -0.0112719">
            <inertial pos="0 -0.133575 0" quat="0.5 0.5 -0.5 0.5" mass="0.700144" diaginertia="0.00454826 0.00419295 0.001"/>
            <joint name="elbow_flex_r" pos="0 0 0" axis="0.226047 0.022269 0.973862" stiffness="0" range="-0.3 2.618"/>
            <geom name="ulna_rv" type="mesh" mesh="ulna_rv"/>
            <!-- <site name="relbinner" pos="-0.000399663 -0.0142889 -0.0456821" size="0.01"/>
            <site name="RElbow" pos="0 0 0" size="0.01"/>
            <site name="relbm" pos="0.0357562 0.00809211 0.0482203" size="0.01"/> -->
            <body name="radius_r" pos="-0.00745535 -0.0144153 0.0289071">
              <inertial pos="0 -0.133575 0" quat="0.5 0.5 -0.5 0.5" mass="0.700144" diaginertia="0.00454826 0.00419295 0.001"/>
              <joint name="pro_sup_r" pos="0 0 0" axis="0.056398 0.998406 0.001952" stiffness="0" range="-0.6 3.1415"/>
              <geom name="radius_rv" type="mesh" mesh="radius_rv"/>
              <!-- <site name="rforearm" pos="-0.0145268 -0.114758 0.0463392" size="0.01"/> -->
              <body name="hand_r" pos="-0.00974948 -0.261376 0.0150836">
                <inertial pos="0 -0.0725565 0" quat="0.5 0.5 -0.5 0.5" mass="0.527269" diaginertia="0.00175335 0.00116715 0.001"/>
                <joint name="wrist_flex_r" pos="0 0 0" axis="0 0 1" stiffness="0" range="-1.22173 1.22173"/>
                <joint name="wrist_dev_r" pos="0 0 0" axis="1 0 0" stiffness="0" range="-0.436332 0.610865"/>
                <geom name="pisiform_rvs" type="mesh" mesh="pisiform_rvs"/>
                <geom name="lunate_rvs" type="mesh" mesh="lunate_rvs"/>
                <geom name="scaphoid_rvs" type="mesh" mesh="scaphoid_rvs"/>
                <geom name="triquetrum_rvs" type="mesh" mesh="triquetrum_rvs"/>
                <geom name="hamate_rvs" type="mesh" mesh="hamate_rvs"/>
                <geom name="capitate_rvs" type="mesh" mesh="capitate_rvs"/>
                <geom name="trapezoid_rvs" type="mesh" mesh="trapezoid_rvs"/>
                <geom name="trapezium_rvs" type="mesh" mesh="trapezium_rvs"/>
                <geom name="metacarpal2_rvs" type="mesh" mesh="metacarpal2_rvs"/>
                <geom name="index_proximal_rvs" type="mesh" mesh="index_proximal_rvs"/>
                <geom name="index_medial_rvs" type="mesh" mesh="index_medial_rvs"/>
                <geom name="index_distal_rvs" type="mesh" mesh="index_distal_rvs"/>
                <geom name="metacarpal3_rvs" type="mesh" mesh="metacarpal3_rvs"/>
                <geom name="middle_proximal_rvs" type="mesh" mesh="middle_proximal_rvs"/>
                <geom name="middle_medial_rvs" type="mesh" mesh="middle_medial_rvs"/>
                <geom name="middle_distal_rvs" type="mesh" mesh="middle_distal_rvs"/>
                <geom name="metacarpal4_rvs" type="mesh" mesh="metacarpal4_rvs"/>
                <geom name="ring_proximal_rvs" type="mesh" mesh="ring_proximal_rvs"/>
                <geom name="ring_medial_rvs" type="mesh" mesh="ring_medial_rvs"/>
                <geom name="ring_distal_rvs" type="mesh" mesh="ring_distal_rvs"/>
                <geom name="metacarpal5_rvs" type="mesh" mesh="metacarpal5_rvs"/>
                <geom name="little_proximal_rvs" type="mesh" mesh="little_proximal_rvs"/>
                <geom name="little_medial_rvs" type="mesh" mesh="little_medial_rvs"/>
                <geom name="little_distal_rvs" type="mesh" mesh="little_distal_rvs"/>
                <geom name="metacarpal1_rvs" type="mesh" mesh="metacarpal1_rvs"/>
                <geom name="thumb_proximal_rvs" type="mesh" mesh="thumb_proximal_rvs"/>
                <geom name="thumb_distal_rvs" type="mesh" mesh="thumb_distal_rvs"/>
                <!-- <site name="rwrithumbside" pos="0.0155423 -0.0179106 0.03832" size="0.01"/>
                <site name="rwripinkieside" pos="-0.0147409 -0.0208474 -0.0339345" size="0.01"/>
                <site name="RWrist" pos="0 0 0" size="0.01"/>
                <site name="RHand" pos="0.0044447 -0.0795391 0.00687257" size="0.01"/>
                <site name="rfin" pos="-0.0157425 -0.0865746 -0.0202781" size="0.01"/>
                <site name="rthumb" pos="0.00937293 -0.0784729 0.038221" size="0.01"/> -->
              </body>
            </body>
          </body>
        </body>
        <body name="humerus_l" pos="0.00339907 0.400239 -0.183151">
          <inertial pos="0 -0.193252 0" quat="0.5 0.5 -0.5 0.5" mass="2.34246" diaginertia="0.0213276 0.0190007 0.00655464"/>
          <joint name="arm_flex_l" pos="0 0 0" axis="0 0 1" range="-1.5708 3.1416"/>
          <joint name="arm_add_l" pos="0 0 0" axis="-1 0 0" range="-3.1415 1.5708"/>
          <joint name="arm_rot_l" pos="0 0 0" axis="0 -1 0" range="-1.5708 1.5708"/>
          <geom name="humerus_lv" type="mesh" mesh="humerus_lv"/>
          <!-- <site name="LShoulder" pos="-0.00986901 -0.0475865 -0.0400896" size="0.01"/>
          <site name="lupperarm" pos="-0.0143887 -0.13254 -0.0641756" size="0.01"/> -->
          <body name="ulna_l" pos="0.0154412 -0.336305 0.0112719">
            <inertial pos="0 -0.133575 0" quat="0.5 0.5 -0.5 0.5" mass="0.700144" diaginertia="0.00454826 0.00419295 0.001"/>
            <joint name="elbow_flex_l" pos="0 0 0" axis="-0.226047 -0.022269 0.973862" stiffness="0" range="-0.3 2.618"/>
            <geom name="ulna_lv" type="mesh" mesh="ulna_lv"/>
            <!-- <site name="lelbinner" pos="-0.000399663 -0.0142889 0.0456821" size="0.01"/>
            <site name="LElbow" pos="0 0 0" size="0.01"/>
            <site name="lelbm" pos="0.0357562 0.00809211 -0.0482203" size="0.01"/> -->
            <body name="radius_l" pos="-0.00745535 -0.0144153 -0.0289071">
              <inertial pos="0 -0.133575 0" quat="0.5 0.5 -0.5 0.5" mass="0.700144" diaginertia="0.00454826 0.00419295 0.001"/>
              <joint name="pro_sup_l" pos="0 0 0" axis="-0.056398 -0.998406 0.001952" stiffness="0" range="-0.6 3.1415"/>
              <geom name="radius_lv" type="mesh" mesh="radius_lv"/>
              <!-- <site name="lforearm" pos="-0.0145268 -0.114758 -0.0463392" size="0.01"/> -->
              <body name="hand_l" pos="-0.00974948 -0.261376 -0.0150836">
                <inertial pos="0 -0.0725565 0" quat="0.5 0.5 -0.5 0.5" mass="0.527269" diaginertia="0.00175335 0.00116715 0.001"/>
                <joint name="wrist_flex_l" pos="0 0 0" axis="0 0 1" stiffness="0" range="-1.22173 1.22173"/>
                <joint name="wrist_dev_l" pos="0 0 0" axis="-1 0 0" stiffness="0" range="-0.436332 0.610865"/>
                <geom name="pisiform_lvs" type="mesh" mesh="pisiform_lvs"/>
                <geom name="lunate_lvs" type="mesh" mesh="lunate_lvs"/>
                <geom name="scaphoid_lvs" type="mesh" mesh="scaphoid_lvs"/>
                <geom name="triquetrum_lvs" type="mesh" mesh="triquetrum_lvs"/>
                <geom name="hamate_lvs" type="mesh" mesh="hamate_lvs"/>
                <geom name="capitate_lvs" type="mesh" mesh="capitate_lvs"/>
                <geom name="trapezoid_lvs" type="mesh" mesh="trapezoid_lvs"/>
                <geom name="trapezium_lvs" type="mesh" mesh="trapezium_lvs"/>
                <geom name="metacarpal2_lvs" type="mesh" mesh="metacarpal2_lvs"/>
                <geom name="index_proximal_lvs" type="mesh" mesh="index_proximal_lvs"/>
                <geom name="index_medial_lvs" type="mesh" mesh="index_medial_lvs"/>
                <geom name="index_distal_lvs" type="mesh" mesh="index_distal_lvs"/>
                <geom name="metacarpal3_lvs" type="mesh" mesh="metacarpal3_lvs"/>
                <geom name="middle_proximal_lvs" type="mesh" mesh="middle_proximal_lvs"/>
                <geom name="middle_medial_lvs" type="mesh" mesh="middle_medial_lvs"/>
                <geom name="middle_distal_lvs" type="mesh" mesh="middle_distal_lvs"/>
                <geom name="metacarpal4_lvs" type="mesh" mesh="metacarpal4_lvs"/>
                <geom name="ring_proximal_lvs" type="mesh" mesh="ring_proximal_lvs"/>
                <geom name="ring_medial_lvs" type="mesh" mesh="ring_medial_lvs"/>
                <geom name="ring_distal_lvs" type="mesh" mesh="ring_distal_lvs"/>
                <geom name="metacarpal5_lvs" type="mesh" mesh="metacarpal5_lvs"/>
                <geom name="little_proximal_lvs" type="mesh" mesh="little_proximal_lvs"/>
                <geom name="little_medial_lvs" type="mesh" mesh="little_medial_lvs"/>
                <geom name="little_distal_lvs" type="mesh" mesh="little_distal_lvs"/>
                <geom name="metacarpal1_lvs" type="mesh" mesh="metacarpal1_lvs"/>
                <geom name="thumb_proximal_lvs" type="mesh" mesh="thumb_proximal_lvs"/>
                <geom name="thumb_distal_lvs" type="mesh" mesh="thumb_distal_lvs"/>
                <!-- <site name="lwrithumbside" pos="0.0155423 -0.0179106 -0.03832" size="0.01"/>
                <site name="lwripinkieside" pos="-0.0147409 -0.0208474 0.0339345" size="0.01"/>
                <site name="LWrist" pos="0 0 0" size="0.01"/>
                <site name="LHand" pos="0.0044447 -0.0795391 -0.00687257" size="0.01"/>
                <site name="lfin" pos="-0.0157425 -0.0865746 0.0202781" size="0.01"/>
                <site name="lthumb" pos="0.00937293 -0.0784729 -0.038221" size="0.01"/> -->
              </body>
            </body>
          </body>
        </body>
      </body>
    </body>
  </worldbody>
  <actuator>
    <general name="mot_lumbar_ext" joint="lumbar_extension" gear="160 0 0 0 0 0"/>
    <general name="mot_lumbar_bend" joint="lumbar_bending" gear="160 0 0 0 0 0"/>
    <general name="mot_lumbar_rot" joint="lumbar_rotation" gear="100 0 0 0 0 0"/>
    <general name="mot_shoulder_flex_r" joint="arm_flex_r" gear="250 0 0 0 0 0"/>
    <general name="mot_shoulder_add_r" joint="arm_add_r" gear="250 0 0 0 0 0"/>
    <general name="mot_shoulder_rot_r" joint="arm_rot_r" gear="250 0 0 0 0 0"/>
    <general name="mot_elbow_flex_r" joint="elbow_flex_r" gear="250 0 0 0 0 0"/>
    <general name="mot_pro_sup_r" joint="pro_sup_r" gear="250 0 0 0 0 0"/>
    <general name="mot_wrist_flex_r" joint="wrist_flex_r" gear="50 0 0 0 0 0"/>
    <general name="mot_wrist_dev_r" joint="wrist_dev_r" gear="50 0 0 0 0 0"/>
    <general name="mot_shoulder_flex_l" joint="arm_flex_l" gear="250 0 0 0 0 0"/>
    <general name="mot_shoulder_add_l" joint="arm_add_l" gear="250 0 0 0 0 0"/>
    <general name="mot_shoulder_rot_l" joint="arm_rot_l" gear="250 0 0 0 0 0"/>
    <general name="mot_elbow_flex_l" joint="elbow_flex_l" gear="250 0 0 0 0 0"/>
    <general name="mot_pro_sup_l" joint="pro_sup_l" gear="250 0 0 0 0 0"/>
    <general name="mot_wrist_flex_l" joint="wrist_flex_l" gear="50 0 0 0 0 0"/>
    <general name="mot_wrist_dev_l" joint="wrist_dev_l" gear="50 0 0 0 0 0"/>
    <general name="mot_hip_flexion_r" joint="hip_flexion_r" gear="275 0 0 0 0 0"/>
    <general name="mot_hip_adduction_r" joint="hip_adduction_r" gear="530 0 0 0 0 0"/>
    <general name="mot_hip_rotation_r" joint="hip_rotation_r" gear="600 0 0 0 0 0"/>
    <general name="mot_knee_angle_r" joint="knee_angle_r" gear="600 0 0 0 0 0"/>
    <general name="mot_ankle_angle_r" joint="ankle_angle_r" gear="500 0 0 0 0 0"/>
    <general name="mot_subtalar_angle_r" joint="subtalar_angle_r" gear="50 0 0 0 0 0"/>
    <general name="mot_mtp_angle_r" joint="mtp_angle_r" gear="50 0 0 0 0 0"/>
    <general name="mot_hip_flexion_l" joint="hip_flexion_l" gear="275 0 0 0 0 0"/>
    <general name="mot_hip_adduction_l" joint="hip_adduction_l" gear="530 0 0 0 0 0"/>
    <general name="mot_hip_rotation_l" joint="hip_rotation_l" gear="600 0 0 0 0 0"/>
    <general name="mot_knee_angle_l" joint="knee_angle_l" gear="600 0 0 0 0 0"/>
    <general name="mot_ankle_angle_l" joint="ankle_angle_l" gear="500 0 0 0 0 0"/>
    <general name="mot_subtalar_angle_l" joint="subtalar_angle_l" gear="50 0 0 0 0 0"/>
    <general name="mot_mtp_angle_l" joint="mtp_angle_l" gear="50 0 0 0 0 0"/>
  </actuator>
</mujoco>
